Workbook

Sheet Datos
B3: DesSeccion | C3: Traducción
B4: Oferta del Día | C4: Oferta del Día
B5: OPM | C5: Ofertas para ti
B6: Oferta Final | C6: Oferta Final
B7: Revista Digital | C7: Ofertas para ti
B8: GND | C8: GND
B9: Ofertas para ti | C9: Ofertas para ti
B10: ShowRoom | C10: ShowRoom

Sheet COMPARACIÓN Tabla Din
A1: 201805
A2: CHILE | G2: COLOMBIA | M2: DIF.
A4: CANAL | G4: CANAL
A5: Etiquetas de fila | B5: Suma de RealVtaDolNeto | C5: Vta Neta % | D5: %CR | E5: P$P Dig. | G5: Etiquetas de fila | H5: Suma de RealVtaDolNeto | I5: Vta Neta % | J5: %CR | K5: P$P Dig.
A6: App Consultora | B6: 39203.692 | C6: =B6/$B$9 -> 0.09476502 | D6: =Chile!E37 -> 0.18495757 | E6: =B6/Chile!C37 -> 31.015579 | G6: App Consultora | H6: 29189.023 | I6: =H6/$H$9 -> 0.11680371 | J6: ='CO Tabla Din'!C4 -> 0.075 | K6: ='CO Tabla Din'!D4 -> 16.324957
A7: Desktop | B7: 196743.58 | C7: =B7/$B$9 -> 0.47557789 | D7: =Chile!E38 -> 0.28340405 | E7: =B7/Chile!C38 -> 24.143279 | G7: Desktop | H7: 156586.65 | I7: =H7/$H$9 -> 0.62660202 | J7: ='CO Tabla Din'!C5 -> 0.14027011 | K7: ='CO Tabla Din'!D5 -> 13.668527
A8: Mobile | B8: 177746.43 | C8: =B8/$B$9 -> 0.42965709 | D8: =Chile!E39 -> 0.28065328 | E8: =B8/Chile!C39 -> 26.119975 | G8: Mobile | H8: 64122.417 | I8: =H8/$H$9 -> 0.25659427 | J8: ='CO Tabla Din'!C6 -> 0.075644783 | K8: ='CO Tabla Din'!D6 -> 12.42201
A9: Total general | B9: 413693.7 | G9: Total general | H9: 249898.09 | L9: =SUMPRODUCT(K6:K8,I6:I8) -> 13.658959
C10: =TRUNC(C6+C8,2)&" Proviene de mobile/app" -> 0.52 Proviene de mobile/app | I10: =TRUNC(I6+I8,2)&" Proviene de mobile/app" -> 0.37 Proviene de mobile/app
A12: SECCIÓN | G12: SECCIÓN
A13: Etiquetas de fila | B13: Suma de RealVtaDolNeto | G13: Etiquetas de fila | H13: Suma de RealVtaDolNeto
A14: Contenedor | B14: 0.34098392 | G14: Contenedor | H14: 0.29021926
A15: Home | B15: 0.061519671 | G15: Home | H15: 0.071797753
A16: Pedido | B16: 0.1500749 | G16: Pedido | H16: 0.17539354
A17: RD Landing | B17: 0.4474215 | G17: Landing Compra | H17: 0.24109281
A18: Total general | B18: 1 | G18: Product Page | H18: 0.21505708
G19: RD Landing | H19: 0.0064395541
G20: Total general | H20: 1
A22: SECCIÓN (SIN SR) | G22: SECCIÓN (SIN SR)
A23: Traducción | B23: (Todas) | G23: Traducción | H23: (Varios elementos)
A25: Etiquetas de fila | B25: Suma de RealVtaDolNeto | G25: Etiquetas de fila | H25: Suma de RealVtaDolNeto
A26: Contenedor | B26: 0.34098392 | G26: Contenedor | H26: 0.51327614
A27: Home | B27: 0.061519671 | G27: Home | H27: 0.099724941
A28: Pedido | B28: 0.1500749 | G28: Pedido | H28: 0.37329349
A29: RD Landing | B29: 0.4474215 | G29: RD Landing | H29: 0.013705429
A30: Total general | B30: 1 | G30: Total general | H30: 1
A34: Etiquetas de fila | B34: Suma de RealVtaDolNeto | G34: Etiquetas de fila | H34: Suma de RealVtaDolNeto
A35: Oferta del Día | G35: Oferta del Día
A36: Contenedor | B36: 0.82958041 | G36: Contenedor | H36: 0.79753927
A37: Pedido | B37: 0.10941393 | G37: Home | H37: 0.046095005
A38: Home | B38: 0.061005655 | G38: Pedido | H38: 0.15636573
A39: Oferta Final | G39: Oferta Final
A40: Pedido | B40: 1 | G40: Pedido | H40: 1
A41: Ofertas para ti | G41: Ofertas para ti
A42: RD Landing | B42: 0.78396454 | G42: Contenedor | H42: 0.38239528
A43: Home | B43: 0.093293607 | G43: Home | H43: 0.16247285
A44: Pedido | B44: 0.067139314 | G44: Pedido | H44: 0.42767152
A45: Contenedor | B45: 0.055602542 | G45: RD Landing | H45: 0.027460352
A46: GND | G46: Total general | H46: 1
A47: Contenedor | B47: 1
...

Sheet CL Tabla Din
A2: CANAL | I2: Etiquetas de fila | J2: Suma de RealVtaDolNeto
A3: Etiquetas de fila | B3: Suma de RealVtaDolNeto | C3: %CR | D3: P$P Dig. | F3: Etiquetas de fila | G3: Suma de RealVtaDolNeto | I3: GND | J3: 81380.727 | K3: GND
A4: App Consultora | B4: 39203.692 | C4: =Chile!E37 -> 0.18495757 | D4: =B4/Chile!D37 -> 5.736566 | F4: Oferta del Día | G4: 56117.902 | I4: Oferta del Día | J4: 56117.902 | K4: OK
A5: Desktop | B5: 196743.58 | C5: =Chile!E38 -> 0.28340405 | D5: =B5/Chile!D38 -> 6.8423029 | F5: Oferta Final | G5: 40093.246 | I5: Oferta Final | J5: 40093.246 | K5: OK
A6: Mobile | B6: 177746.43 | C6: =Chile!E39 -> 0.28065328 | D6: =B6/Chile!D39 -> 7.3306565 | F6: Ofertas para ti | G6: 236101.82 | I6: Ofertas para ti | J6: 3462.7425 | K6: OPT
A7: Total general | B7: 413693.7 | F7: GND | G7: 81380.727 | I7: OPM | J7: 47543.624 | K7: OPT
F8: Total general | G8: 413693.7 | I8: Revista Digital | J8: 185095.46 | K8: OPT
I9: Total general | J9: 413693.7
A10: SECCIÓN
A11: Etiquetas de fila | B11: Suma de RealVtaDolNeto
A12: RD Landing | B12: 0.4474215
A13: Contenedor | B13: 0.34098392 | F13: Suma de RealVtaDolNeto | G13: Etiquetas de columna
A14: Pedido | B14: 0.1500749 | F14: Etiquetas de fila | G14: Contenedor | H14: Home | I14: Pedido | J14: RD Landing | K14: Total general
A15: Home | B15: 0.061519671 | F15: Oferta del Día | G15: 46554.312 | H15: 3423.5094 | I15: 6140.0805 | K15: 56117.902
A16: Total general | B16: 1 | F16: Oferta Final | I16: 40093.246 | K16: 40093.246
F17: Ofertas para ti | G17: 13127.861 | H17: 22026.791 | I17: 15851.714 | J17: 185095.46 | K17: 236101.82
A18: Etiquetas de fila | B18: Suma de RealVtaDolNeto | F18: GND | G18: 81380.727 | K18: 81380.727
A19: Oferta del Día | F19: Total general | G19: 141062.9 | H19: 25450.3 | I19: 62085.041 | J19: 185095.46 | K19: 413693.7
A20: Contenedor | B20: 0.82958041
A21: Pedido | B21: 0.10941393
A22: Home | B22: 0.061005655
A23: Oferta Final
A24: Pedido | B24: 1
A25: Ofertas para ti
A26: RD Landing | B26: 0.78396454
A27: Home | B27: 0.093293607
A28: Pedido | B28: 0.067139314
A29: Contenedor | B29: 0.055602542
A30: GND
A31: Contenedor | B31: 1
A32: Total general | B32: 1

Sheet CO Tabla Din
A2: CANAL
A3: Etiquetas de fila | B3: Suma de RealVtaDolNeto | C3: %CR | D3: P$P Dig. | F3: Etiquetas de fila | G3: Suma de RealVtaDolNeto
A4: App Consultora | B4: 29189.023 | C4: =Colombia!E41 -> 0.075 | D4: =B4/Colombia!C41 -> 16.324957 | F4: Oferta del Día | G4: 47467.92
A5: Desktop | B5: 156586.65 | C5: =Colombia!E42 -> 0.14027011 | D5: =B5/Colombia!C42 -> 13.668527 | F5: Oferta Final | G5: 11345.737
A6: Mobile | B6: 64122.417 | C6: =Colombia!E43 -> 0.075644783 | D6: =B6/Colombia!C43 -> 12.42201 | F6: Ofertas para ti | G6: 58602.027
A7: Total general | B7: 249898.09 | F7: ShowRoom | G7: 132482.4
F8: Total general | G8: 249898.09
A10: SECCIÓN
A11: Etiquetas de fila | B11: Suma de RealVtaDolNeto
A12: Contenedor | B12: 0.29021926
A13: Landing Compra | B13: 0.24109281 | F13: Suma de RealVtaDolNeto | G13: Etiquetas de columna
A14: Product Page | B14: 0.21505708 | F14: Etiquetas de fila | G14: Contenedor | H14: Home | I14: Pedido | J14: RD Landing | K14: Product Page | L14: Landing Compra | M14: Total general
A15: Pedido | B15: 0.17539354 | F15: Oferta del Día | G15: 37857.53 | H15: 2188.034 | I15: 7422.3559 | M15: 47467.92
A16: Home | B16: 0.071797753 | F16: Oferta Final | I16: 11345.737 | M16: 11345.737
A17: RD Landing | B17: 0.0064395541 | F17: Ofertas para ti | G17: 22409.139 | H17: 9521.2381 | I17: 25062.418 | J17: 1609.2323 | M17: 58602.027
A18: Total general | B18: 1 | F18: ShowRoom | G18: 12258.571 | H18: 6232.8492 | K18: 53742.353 | L18: 60248.632 | M18: 132482.4
F19: Total general | G19: 72525.239 | H19: 17942.121 | I19: 43830.511 | J19: 1609.2323 | K19: 53742.353 | L19: 60248.632 | M19: 249898.09
A22: Etiquetas de fila | B22: Suma de RealVtaDolNeto
A23: Oferta del Día
A24: Contenedor | B24: 0.79753927
A25: Pedido | B25: 0.15636573
A26: Home | B26: 0.046095005
A27: Oferta Final
A28: Pedido | B28: 1
A29: Ofertas para ti
A30: Pedido | B30: 0.42767152
A31: Contenedor | B31: 0.38239528
A32: Home | B32: 0.16247285
A33: RD Landing | B33: 0.027460352
A34: ShowRoom
A35: Landing Compra | B35: 0.45476705
A36: Product Page | B36: 0.40565653
A37: Contenedor | B37: 0.092529803
A38: Home | B38: 0.047046619
A39: Total general | B39: 1

Sheet Hoja6
A1: DesMedio | B1: DesZona | C1: DesSeccion | D1: consultoras | E1: RealVtaDolNeto | F1: Traducción | G1: DesSeccion2
A2: Mobile | B2: RD Landing | C2: Revista Digital | D2: 54 | E2: 591.57631 | F2: Ofertas para ti | G2: RD Landing
A3: Desktop | B3: RD Landing | C3: Revista Digital | D3: 81 | E3: 783.37325 | F3: Ofertas para ti | G3: RD Landing
A4: Desktop | B4: RD Landing | C4: Revista Digital | D4: 1 | E4: 5.5802093 | F4: Ofertas para ti | G4: RD Landing
A5: App Consultora | B5: RD Landing | C5: Revista Digital | D5: 21 | E5: 228.7025 | F5: Ofertas para ti | G5: RD Landing

Sheet Chile
A2: 1) | B2: ¿Por qué página se genera la mayor venta? | D2: 2018-05
B4: DesMedio | C4: DesZona | D4: DesSeccion | E4: consultoras | F4: RealVtaDolNeto | G4: Traducción | H4: DesZona2 | J4: DesSeccion | K4: DesMedio | L4: DesZona | M4: consultoras | N4: RealVtaDolNeto | O4: Traducción
B5: App Consultora | C5: General | D5: Oferta del Día | E5: 313 | F5: 6387.5076 | G5: =INDEX(Datos!$C$4:$C$9,MATCH(D5,Datos!$B$4:$B$9,0),1) -> Oferta del Día | H5: =IF(C5="General","Contenedor",C5) -> Contenedor | J5: Revista Digital | K5: App Consultora | L5: RD Landing | M5: 234 | N5: 6226.06 | O5: =INDEX(Datos!$C$4:$C$9,MATCH(J5,Datos!$B$4:$B$9,0),1) -> Ofertas para ti
B6: App Consultora | C6: Home | D6: OPM | E6: 77 | F6: 2041.5031 | G6: =INDEX(Datos!$C$4:$C$9,MATCH(D6,Datos!$B$4:$B$9,0),1) -> Ofertas para ti | H6: =IF(C6="General","Contenedor",C6) -> Home | J6: Revista Digital | K6: Mobile | L6: RD Landing | M6: 638 | N6: 15728.37 | O6: =INDEX(Datos!$C$4:$C$9,MATCH(J6,Datos!$B$4:$B$9,0),1) -> Ofertas para ti
B7: App Consultora | C7: Pedido | D7: Oferta Final | E7: 300 | F7: 2715.2938 | G7: =INDEX(Datos!$C$4:$C$9,MATCH(D7,Datos!$B$4:$B$9,0),1) -> Oferta Final | H7: =IF(C7="General","Contenedor",C7) -> Pedido | J7: GND | K7: Desktop | L7: Contenedor | M7: 1654 | N7: 45515.356 | O7: =INDEX(Datos!$C$4:$C$9,MATCH(J7,Datos!$B$4:$B$9,0),1) -> GND
B8: App Consultora | C8: Pedido | D8: OPM | E8: 8 | F8: 142.77583 | G8: =INDEX(Datos!$C$4:$C$9,MATCH(D8,Datos!$B$4:$B$9,0),1) -> Ofertas para ti | H8: =IF(C8="General","Contenedor",C8) -> Pedido | J8: GND | K8: Mobile | L8: Contenedor | M8: 1296 | N8: 35865.371 | O8: =INDEX(Datos!$C$4:$C$9,MATCH(J8,Datos!$B$4:$B$9,0),1) -> GND
B9: App Consultora | C9: RD Landing | D9: Revista Digital | E9: 234 | F9: 6226.06 | G9: =INDEX(Datos!$C$4:$C$9,MATCH(D9,Datos!$B$4:$B$9,0),1) -> Ofertas para ti | H9: =IF(C9="General","Contenedor",C9) -> RD Landing | J9: Oferta del Día | K9: App Consultora | L9: General | M9: 313 | N9: 6387.5076 | O9: =INDEX(Datos!$C$4:$C$9,MATCH(J9,Datos!$B$4:$B$9,0),1) -> Oferta del Día
B10: App Consultora | C10: RD Landing | D10: Revista Digital | E10: 805 | F10: 21643.739 | G10: =INDEX(Datos!$C$4:$C$9,MATCH(D10,Datos!$B$4:$B$9,0),1) -> Ofertas para ti | H10: =IF(C10="General","Contenedor",C10) -> RD Landing | J10: Oferta del Día | K10: Desktop | L10: General | M10: 730 | N10: 14547.913 | O10: =INDEX(Datos!$C$4:$C$9,MATCH(J10,Datos!$B$4:$B$9,0),1) -> Oferta del Día
B11: App Consultora | C11: RD Landing | D11: Revista Digital | E11: 3 | F11: 46.812642 | G11: =INDEX(Datos!$C$4:$C$9,MATCH(D11,Datos!$B$4:$B$9,0),1) -> Ofertas para ti | H11: =IF(C11="General","Contenedor",C11) -> RD Landing | J11: Oferta del Día | K11: Desktop | L11: Home | M11: 186 | N11: 3423.5094 | O11: =INDEX(Datos!$C$4:$C$9,MATCH(J11,Datos!$B$4:$B$9,0),1) -> Oferta del Día
B12: Desktop | C12: Contenedor | D12: GND | E12: 1654 | F12: 45515.356 | G12: =INDEX(Datos!$C$4:$C$9,MATCH(D12,Datos!$B$4:$B$9,0),1) -> GND | H12: =IF(C12="General","Contenedor",C12) -> Contenedor | J12: Oferta del Día | K12: Desktop | L12: Pedido | M12: 330 | N12: 6140.0805 | O12: =INDEX(Datos!$C$4:$C$9,MATCH(J12,Datos!$B$4:$B$9,0),1) -> Oferta del Día
B13: Desktop | C13: Contenedor | D13: OPM | E13: 556 | F13: 13127.861 | G13: =INDEX(Datos!$C$4:$C$9,MATCH(D13,Datos!$B$4:$B$9,0),1) -> Ofertas para ti | H13: =IF(C13="General","Contenedor",C13) -> Contenedor | J13: Oferta del Día | K13: Mobile | L13: General | M13: 1279 | N13: 25618.892 | O13: =INDEX(Datos!$C$4:$C$9,MATCH(J13,Datos!$B$4:$B$9,0),1) -> Oferta del Día
B14: Desktop | C14: General | D14: Oferta del Día | E14: 730 | F14: 14547.913 | G14: =INDEX(Datos!$C$4:$C$9,MATCH(D14,Datos!$B$4:$B$9,0),1) -> Oferta del Día | H14: =IF(C14="General","Contenedor",C14) -> Contenedor | J14: Oferta Final | K14: App Consultora | L14: Pedido | M14: 300 | N14: 2715.2938 | O14: =INDEX(Datos!$C$4:$C$9,MATCH(J14,Datos!$B$4:$B$9,0),1) -> Oferta Final
B15: Desktop | C15: Home | D15: Oferta del Día | E15: 186 | F15: 3423.5094 | G15: =INDEX(Datos!$C$4:$C$9,MATCH(D15,Datos!$B$4:$B$9,0),1) -> Oferta del Día | H15: =IF(C15="General","Contenedor",C15) -> Home | J15: Oferta Final | K15: Desktop | L15: Pedido | M15: 2686 | N15: 26632.934 | O15: =INDEX(Datos!$C$4:$C$9,MATCH(J15,Datos!$B$4:$B$9,0),1) -> Oferta Final
B16: Desktop | C16: Home | D16: Ofertas para ti | E16: 187 | F16: 3462.7425 | G16: =INDEX(Datos!$C$4:$C$9,MATCH(D16,Datos!$B$4:$B$9,0),1) -> Ofertas para ti | H16: =IF(C16="General","Contenedor",C16) -> Home | J16: Oferta Final | K16: Mobile | L16: Pedido | M16: 1138 | N16: 10745.018 | O16: =INDEX(Datos!$C$4:$C$9,MATCH(J16,Datos!$B$4:$B$9,0),1) -> Oferta Final
... B31: Mobile | C31: RD Landing | D31: Revista Digital | E31: 6 | F31: 145.16833 | G31: =INDEX(Datos!$C$4:$C$9,MATCH(D31,Datos!$B$4:$B$9,0),1) -> Ofertas para ti | H31: =IF(C31="General","Contenedor",C31) -> RD Landing | J31: Revista Digital | K31: Desktop | L31: RD Landing | M31: 2114 | N31: 58267.078 | O31: =INDEX(Datos!$C$4:$C$9,MATCH(J31,Datos!$B$4:$B$9,0),1) -> Ofertas para ti
F32: =SUM(F5:F31) -> 413693.7 | N32: =SUM(N5:N31) -> 413693.7
A34: 2) | B34: ¿Cómo varía el CR por desktop, mobile y app?
B36: DesMedio | C36: Consultoras_N | D36: Consultoras_D | E36: CR
B37: App Consultora | C37: 1264 | D37: 6834 | E37: =C37/D37 -> 0.18495757
B38: Desktop | C38: 8149 | D38: 28754 | E38: =C38/D38 -> 0.28340405
B39: Mobile | C39: 6805 | D39: 24247 | E39: =C39/D39 -> 0.28065328
B40: TOTAL | C40: =SUM(C37:C39) -> 16218 | D40: =SUM(D37:D39) -> 59835 | E40: =C40/D40 -> 0.27104537
B44: Etiquetas de fila | C44: Suma de RealVtaDolNeto
B45: Revista Digital | C45: 185095.46
B46: GND | C46: 81380.727
B47: Oferta del Día | C47: 56117.902 | D47: OK
B48: OPM | C48: 47543.624
B49: Oferta Final | C49: 40093.246 | D49: OK
B50: Ofertas para ti | C50: 3462.7425
B51: Total general | C51: 413693.7

Sheet Colombia
A2: 1) | B2: ¿Por qué página se genera la mayor venta?
B4: DesMedio | C4: DesZona | D4: DesSeccion | E4: consultoras | F4: RealVtaDolNeto | G4: Traducción | H4: DesSeccion2 | J4: DesSeccion | K4: DesMedio | L4: DesZona | M4: consultoras | N4: RealVtaDolNeto | O4: Traducción
B5: App Consultora | C5: Contenedor | D5: Ofertas para ti | E5: 505 | F5: 5298.2944 | G5: =INDEX(Datos!$C$4:$C$10,MATCH(D5,Datos!$B$4:$B$10,0),1) -> Ofertas para ti | H5: =IF(C5="General","Contenedor",C5) -> Contenedor | J5: ShowRoom | K5: Desktop | L5: Home | M5: 349 | N5: 6232.8492 | O5: =INDEX(Datos!$C$4:$C$10,MATCH(J5,Datos!$B$4:$B$10,0),1) -> ShowRoom
B6: App Consultora | C6: General | D6: Oferta del Día | E6: 591 | F6: 9413.5247 | G6: =INDEX(Datos!$C$4:$C$10,MATCH(D6,Datos!$B$4:$B$10,0),1) -> Oferta del Día | H6: =IF(C6="General","Contenedor",C6) -> Contenedor | J6: Showroom | K6: Desktop | L6: Landing Compra | M6: 3101 | N6: 60248.632 | O6: =INDEX(Datos!$C$4:$C$10,MATCH(J6,Datos!$B$4:$B$10,0),1) -> ShowRoom
B7: App Consultora | C7: Home | D7: Ofertas para ti | E7: 1 | F7: 5.4621539 | G7: =INDEX(Datos!$C$4:$C$10,MATCH(D7,Datos!$B$4:$B$10,0),1) -> Ofertas para ti | H7: =IF(C7="General","Contenedor",C7) -> Home | J7: Oferta del Día | K7: App Consultora | L7: General | M7: 591 | N7: 9413.5247 | O7: =INDEX(Datos!$C$4:$C$10,MATCH(J7,Datos!$B$4:$B$10,0),1) -> Oferta del Día
B8: App Consultora | C8: Home | D8: OPM | E8: 2 | F8: 18.276748 | G8: =INDEX(Datos!$C$4:$C$10,MATCH(D8,Datos!$B$4:$B$10,0),1) -> Ofertas para ti | H8: =IF(C8="General","Contenedor",C8) -> Home | J8: Oferta del Día | K8: Desktop | L8: General | M8: 1093 | N8: 16405.202 | O8: =INDEX(Datos!$C$4:$C$10,MATCH(J8,Datos!$B$4:$B$10,0),1) -> Oferta del Día
B9: App Consultora | C9: Pedido | D9: Oferta Final | E9: 189 | F9: 1861.4786 | G9: =INDEX(Datos!$C$4:$C$10,MATCH(D9,Datos!$B$4:$B$10,0),1) -> Oferta Final | H9: =IF(C9="General","Contenedor",C9) -> Pedido | J9: Oferta del Día | K9: Desktop | L9: Home | M9: 148 | N9: 2188.034 | O9: =INDEX(Datos!$C$4:$C$10,MATCH(J9,Datos!$B$4:$B$10,0),1) -> Oferta del Día
B10: App Consultora | C10: RD Landing | D10: Revista Digital | E10: 21 | F10: 228.7025 | G10: =INDEX(Datos!$C$4:$C$10,MATCH(D10,Datos!$B$4:$B$10,0),1) -> Ofertas para ti | H10: =IF(C10="General","Contenedor",C10) -> RD Landing | J10: Oferta del Día | K10: Desktop | L10: Pedido | M10: 493 | N10: 7422.3559 | O10: =INDEX(Datos!$C$4:$C$10,MATCH(J10,Datos!$B$4:$B$10,0),1) -> Oferta del Día
B11: App Consultora | C11: Product Page | D11: Showroom | E11: 638 | F11: 12363.284 | G11: =INDEX(Datos!$C$4:$C$10,MATCH(D11,Datos!$B$4:$B$10,0),1) -> ShowRoom | H11: =IF(C11="General","Contenedor",C11) -> Product Page | J11: Oferta del Día | K11: Mobile | L11: General | M11: 775 | N11: 12038.803 | O11: =INDEX(Datos!$C$4:$C$10,MATCH(J11,Datos!$B$4:$B$10,0),1) -> Oferta del Día
B12: Desktop | C12: Contenedor | D12: Ofertas para ti | E12: 969 | F12: 9455.3012 | G12: =INDEX(Datos!$C$4:$C$10,MATCH(D12,Datos!$B$4:$B$10,0),1) -> Ofertas para ti | H12: =IF(C12="General","Contenedor",C12) -> Contenedor | J12: Oferta Final | K12: App Consultora | L12: Pedido | M12: 189 | N12: 1861.4786 | O12: =INDEX(Datos!$C$4:$C$10,MATCH(J12,Datos!$B$4:$B$10,0),1) -> Oferta Final
B13: Desktop | C13: Contenedor | D13: OPM | E13: 30 | F13: 326.96435 | G13: =INDEX(Datos!$C$4:$C$10,MATCH(D13,Datos!$B$4:$B$10,0),1) -> Ofertas para ti | H13: =IF(C13="General","Contenedor",C13) -> Contenedor | J13: Oferta Final | K13: Desktop | L13: Pedido | M13: 539 | N13: 5657.8223 | O13: =INDEX(Datos!$C$4:$C$10,MATCH(J13,Datos!$B$4:$B$10,0),1) -> Oferta Final
B14: Desktop | C14: Contenedor | D14: Showroom | E14: 703 | F14: 12258.571 | G14: =INDEX(Datos!$C$4:$C$10,MATCH(D14,Datos!$B$4:$B$10,0),1) -> ShowRoom | H14: =IF(C14="General","Contenedor",C14) -> Contenedor | J14: Oferta Final | K14: Mobile | L14: Pedido | M14: 400 | N14: 3826.4357 | O14: =INDEX(Datos!$C$4:$C$10,MATCH(J14,Datos!$B$4:$B$10,0),1) -> Oferta Final
B15: Desktop | C15: General | D15: Oferta del Día | E15: 1093 | F15: 16405.202 | G15: =INDEX(Datos!$C$4:$C$10,MATCH(D15,Datos!$B$4:$B$10,0),1) -> Oferta del Día | H15: =IF(C15="General","Contenedor",C15) -> Contenedor | J15: Ofertas para ti | K15: App Consultora | L15: Contenedor | M15: 505 | N15: 5298.2944 | O15: =INDEX(Datos!$C$4:$C$10,MATCH(J15,Datos!$B$4:$B$10,0),1) -> Ofertas para ti
B16: Desktop | C16: Home | D16: Oferta del Día | E16: 148 | F16: 2188.034 | G16: =INDEX(Datos!$C$4:$C$10,MATCH(D16,Datos!$B$4:$B$10,0),1) -> Oferta del Día | H16: =IF(C16="General","Contenedor",C16) -> Home | J16: Ofertas para ti | K16: App Consultora | L16: Home | M16: 1 | N16: 5.4621539 | O16: =INDEX(Datos!$C$4:$C$10,MATCH(J16,Datos!$B$4:$B$10,0),1) -> Ofertas para ti
... B33: Mobile | C33: Product Page | D33: Showroom | E33: 1682 | F33: 34356.173 | G33: =INDEX(Datos!$C$4:$C$10,MATCH(D33,Datos!$B$4:$B$10,0),1) -> ShowRoom | H33: =IF(C33="General","Contenedor",C33) -> Product Page | J33: ShowRoom | K33: Desktop | L33: Contenedor | M33: 703 | N33: 12258.571 | O33: =INDEX(Datos!$C$4:$C$10,MATCH(J33,Datos!$B$4:$B$10,0),1) -> ShowRoom
F34: =SUM(F5:F33) -> 249898.09 | N34: =SUM(N5:N33) -> 249898.09
A38: 2) | B38: ¿Cómo varía el CR por desktop, mobile y app?
B40: DesMedio | C40: Consultoras_N | D40: Consultoras_D | E40: CR
B41: App Consultora | C41: 1788 | D41: 23840 | E41: =C41/D41 -> 0.075
B42: Desktop | C42: 11456 | D42: 81671 | E42: =C42/D42 -> 0.14027011
B43: Mobile | C43: 5162 | D43: 68240 | E43: =C43/D43 -> 0.075644783
B44: TOTAL | C44: =SUM(C41:C43) -> 18406 | D44: =SUM(D41:D43) -> 173751 | E44: =C44/D44 -> 0.1059332
